Workbook

Sheet Read Me
A1: Basketball Scoring Log - Dear Data 100
A2: One row per score in the Monday and Wednesday games. Aim for 100+ observations.
A4: How to use
A5: 1 | B5: Fix your columns and codes (see the Codes sheet) before the first session and keep them the same.
A6: 2 | B6: During or straight after each game, jot one line per score in your phone, e.g. J,2,LAY,Y. You can't write while playing, so ask a teammate to log or write it up straight after the game.
A7: 3 | B7: Type the lines into the Score Log sheet (blue text = your entries). Drop-downs keep the codes consistent.
A8: 4 | B8: Check the 'check' column on the Score Log: it flags a points value that doesn't match the type code.
A9: 5 | B9: After each session, save columns A-G of the Score Log as a .csv file and commit it to your GitHub repo.
A10: 6 | B10: Tick the session as committed on the Sessions sheet to see your estimated GitHub marks.
A12: Colour key
A13: Blue text | B13: Input you type or can change (scores, targets, rules from the brief).
A14: Black text | B14: Formula - don't overwrite.
A15: Green text | B15: Pulled from another sheet.
A16: Yellow fill | B16: Key assumption cell on the Summary sheet.
A17: Grey fill | B17: Helper column, not part of your exported data.
A19: Example row (format only - do NOT enter this in the log)
A20: id | B20: date | C20: game | D20: scorer | E20: points | F20: type | G20: assisted
A21: 1 | B21: 46314 | C21: 1 | D21: J | E21: 2 | F21: LAYUP | G21: Y
A23: Notes and assumptions
A24: - | B24: Stay anonymous: use initials or codes for scorers, never full names.
A25: - | B25: Record points as actually played. If a game uses 1s and 2s instead of 2s and 3s, log what was awarded.
A26: - | B26: Keep OTHER small. If it passes about 10% of your 2-pointers, give the common ones their own code early.
A27: - | B27: Collect a few more than 100 so you have slack for mistakes (buffer set on the Summary sheet).
A28: - | B28: Mark rates (1 per item in Part 1, 0.25 per item in Part 2, GitHub 5 per commit day) come from the Dear Data 100 assessment brief.
A29: - | B29: Session dates on the Sessions sheet are my suggested plan: Mondays and Wednesdays from 19 Oct 2026. Edit them as needed.
A30: - | B30: The sheet holds 500 score rows. If you need more, copy the last row down and extend the ranges on Summary and Sessions.

Sheet Score Log
A1: id | B1: date | C1: game | D1: scorer | E1: points | F1: type | G1: assisted | H1: check (helper)
H2: =IF(E2="","",IF(F2="","check type",IF(IFERROR(INDEX(Codes!$B$3:$B$14,MATCH(F2,Codes!$A$3:$A$14,0)),0)=E2,"OK","points/type mismatch")))
H3: =IF(E3="","",IF(F3="","check type",IF(IFERROR(INDEX(Codes!$B$3:$B$14,MATCH(F3,Codes!$A$3:$A$14,0)),0)=E3,"OK","points/type mismatch")))
H4: =IF(E4="","",IF(F4="","check type",IF(IFERROR(INDEX(Codes!$B$3:$B$14,MATCH(F4,Codes!$A$3:$A$14,0)),0)=E4,"OK","points/type mismatch")))
H5: =IF(E5="","",IF(F5="","check type",IF(IFERROR(INDEX(Codes!$B$3:$B$14,MATCH(F5,Codes!$A$3:$A$14,0)),0)=E5,"OK","points/type mismatch")))
H6: =IF(E6="","",IF(F6="","check type",IF(IFERROR(INDEX(Codes!$B$3:$B$14,MATCH(F6,Codes!$A$3:$A$14,0)),0)=E6,"OK","points/type mismatch")))
H7: =IF(E7="","",IF(F7="","check type",IF(IFERROR(INDEX(Codes!$B$3:$B$14,MATCH(F7,Codes!$A$3:$A$14,0)),0)=E7,"OK","points/type mismatch")))
H8: =IF(E8="","",IF(F8="","check type",IF(IFERROR(INDEX(Codes!$B$3:$B$14,MATCH(F8,Codes!$A$3:$A$14,0)),0)=E8,"OK","points/type mismatch")))
H9: =IF(E9="","",IF(F9="","check type",IF(IFERROR(INDEX(Codes!$B$3:$B$14,MATCH(F9,Codes!$A$3:$A$14,0)),0)=E9,"OK","points/type mismatch")))
H10: =IF(E10="","",IF(F10="","check type",IF(IFERROR(INDEX(Codes!$B$3:$B$14,MATCH(F10,Codes!$A$3:$A$14,0)),0)=E10,"OK","points/type mismatch")))
H11: =IF(E11="","",IF(F11="","check type",IF(IFERROR(INDEX(Codes!$B$3:$B$14,MATCH(F11,Codes!$A$3:$A$14,0)),0)=E11,"OK","points/type mismatch")))
H12: =IF(E12="","",IF(F12="","check type",IF(IFERROR(INDEX(Codes!$B$3:$B$14,MATCH(F12,Codes!$A$3:$A$14,0)),0)=E12,"OK","points/type mismatch")))
H13: =IF(E13="","",IF(F13="","check type",IF(IFERROR(INDEX(Codes!$B$3:$B$14,MATCH(F13,Codes!$A$3:$A$14,0)),0)=E13,"OK","points/type mismatch")))
... H501: =IF(E501="","",IF(F501="","check type",IF(IFERROR(INDEX(Codes!$B$3:$B$14,MATCH(F501,Codes!$A$3:$A$14,0)),0)=E501,"OK","points/type mismatch")))

Sheet Codes
A1: Scoring type codes
A2: Code | B2: Points | C2: Meaning
A3: FT | B3: 1 | C3: Free throw (or a 1-point score under pickup rules)
A4: LAYUP | B4: 2 | C4: Layup at the rim
A5: DUNK | B5: 2 | C5: Dunk
A6: FLOAT | B6: 2 | C6: Floater or runner over a defender
A7: JUMPER | B7: 2 | C7: Mid-range jump shot inside the arc
A8: HOOK | B8: 2 | C8: Hook shot
A9: PUTBACK | B9: 2 | C9: Offensive rebound put-back
A10: TIPIN | B10: 2 | C10: Tip-in
A11: OTHER | B11: 2 | C11: Any other 2-pointer (keep this rare)
A12: THREE | B12: 3 | C12: Three-pointer, no location noted
A13: CORNER | B13: 3 | C13: Corner three
A14: WING | B14: 3 | C14: Wing or top-of-key three
A16: Add or rename codes here (keep within rows 3-14 so the drop-down and Summary pick them up). Fix them before you start.

Sheet Summary
A1: Summary - how your data is shaping up
A3: Targets and rates (from the assessment brief)
A4: Items needed for full Part 2 data marks | B4: 100 | C4: Part 2: 100 items for full marks.
A5: Extra buffer to collect | B5: 10 | C5: Slack for mistakes; change as you like.
A6: Collection goal | B6: =B4+B5 -> 110 | C6: Target plus buffer.
A7: Part 1: marks per data item shown | B7: 1 | C7: 1 mark per item.
A8: Part 1: maximum data marks | B8: 25 | C8: Capped at 25.
A9: Part 2: marks per data item | B9: 0.25 | C9: 0.25 marks per item.
A10: Part 2: maximum data marks | B10: 25 | C10: Capped at 25.
A12: Progress
A13: Scores logged | B13: =COUNT('Score Log'!$E$2:$E$501) -> 0 | C13: Count of rows with a points value.
A14: Progress to collection goal | B14: =IF(B6=0,0,MIN(B13/B6,1)) -> 0
A15: Scores still needed for goal | B15: =MAX(B6-B13,0) -> 110
A16: Part 1 data marks (estimate, out of 25) | B16: =MIN(B13*B7,B8) -> 0 | C16: If you showed all logged items at the check-in.
A17: Part 2 data marks (estimate, out of 25) | B17: =MIN(B13*B9,B10) -> 0 | C17: 100 items = 25.
A18: Rows needing a check | B18: =COUNTIF('Score Log'!$H$2:$H$501,"points/type mismatch")+COUNTIF('Score Log'!$H$2:$H$501,"check type") -> 0 | C18: Fix these on the Score Log (see the check column).
A20: Scores by point value
A21: Points | B21: Scores | C21: Share of scores | D21: Total points
A22: 1 | B22: =COUNTIF('Score Log'!$E$2:$E$501,A22) -> 0 | C22: =IF($B$13=0,0,B22/$B$13) -> 0 | D22: =A22*B22 -> 0
A23: 2 | B23: =COUNTIF('Score Log'!$E$2:$E$501,A23) -> 0 | C23: =IF($B$13=0,0,B23/$B$13) -> 0 | D23: =A23*B23 -> 0
A24: 3 | B24: =COUNTIF('Score Log'!$E$2:$E$501,A24) -> 0 | C24: =IF($B$13=0,0,B24/$B$13) -> 0 | D24: =A24*B24 -> 0
A25: Total | B25: =SUM(B22:B24) -> 0 | C25: =SUM(C22:C24) -> 0 | D25: =SUM(D22:D24) -> 0
A27: Scores by type
A28: Type code | B28: Points | C28: Scores | D28: Share of scores
A29: =Codes!A3 -> FT | B29: =Codes!B3 -> 1 | C29: =COUNTIF('Score Log'!$F$2:$F$501,A29) -> 0 | D29: =IF($B$13=0,0,C29/$B$13) -> 0
A30: =Codes!A4 -> LAYUP | B30: =Codes!B4 -> 2 | C30: =COUNTIF('Score Log'!$F$2:$F$501,A30) -> 0 | D30: =IF($B$13=0,0,C30/$B$13) -> 0
A31: =Codes!A5 -> DUNK | B31: =Codes!B5 -> 2 | C31: =COUNTIF('Score Log'!$F$2:$F$501,A31) -> 0 | D31: =IF($B$13=0,0,C31/$B$13) -> 0
A32: =Codes!A6 -> FLOAT | B32: =Codes!B6 -> 2 | C32: =COUNTIF('Score Log'!$F$2:$F$501,A32) -> 0 | D32: =IF($B$13=0,0,C32/$B$13) -> 0
A33: =Codes!A7 -> JUMPER | B33: =Codes!B7 -> 2 | C33: =COUNTIF('Score Log'!$F$2:$F$501,A33) -> 0 | D33: =IF($B$13=0,0,C33/$B$13) -> 0
A34: =Codes!A8 -> HOOK | B34: =Codes!B8 -> 2 | C34: =COUNTIF('Score Log'!$F$2:$F$501,A34) -> 0 | D34: =IF($B$13=0,0,C34/$B$13) -> 0
A35: =Codes!A9 -> PUTBACK | B35: =Codes!B9 -> 2 | C35: =COUNTIF('Score Log'!$F$2:$F$501,A35) -> 0 | D35: =IF($B$13=0,0,C35/$B$13) -> 0
A36: =Codes!A10 -> TIPIN | B36: =Codes!B10 -> 2 | C36: =COUNTIF('Score Log'!$F$2:$F$501,A36) -> 0 | D36: =IF($B$13=0,0,C36/$B$13) -> 0
A37: =Codes!A11 -> OTHER | B37: =Codes!B11 -> 2 | C37: =COUNTIF('Score Log'!$F$2:$F$501,A37) -> 0 | D37: =IF($B$13=0,0,C37/$B$13) -> 0
A38: =Codes!A12 -> THREE | B38: =Codes!B12 -> 3 | C38: =COUNTIF('Score Log'!$F$2:$F$501,A38) -> 0 | D38: =IF($B$13=0,0,C38/$B$13) -> 0
A39: =Codes!A13 -> CORNER | B39: =Codes!B13 -> 3 | C39: =COUNTIF('Score Log'!$F$2:$F$501,A39) -> 0 | D39: =IF($B$13=0,0,C39/$B$13) -> 0
A40: =Codes!A14 -> WING | B40: =Codes!B14 -> 3 | C40: =COUNTIF('Score Log'!$F$2:$F$501,A40) -> 0 | D40: =IF($B$13=0,0,C40/$B$13) -> 0
A41: Total | C41: =SUM(C29:C40) -> 0 | D41: =SUM(D29:D40) -> 0
A43: Quality checks
A44: OTHER as a share of all 2-pointers | B44: =IF($B$23=0,0,C37/$B$23) -> 0 | C44: =IF(B44>$B$45,"Over the limit: promote common OTHER types to their own code","OK") -> OK
A45: Limit for OTHER (share of 2s) | B45: 0.1 | C45: Rule of thumb from my suggestion (about 10%).
...

Sheet Sessions
A1: Sessions and GitHub tracker
A2: Planned dates are Mondays and Wednesdays from 19 Oct 2026 - edit to match when you actually play. Mark Y once you've committed that day's .csv.
A3: Date | B3: Day | C3: Scores logged | D3: GitHub commit made? (Y/N) | E3: Notes | G3: Measure | H3: Value
A4: 46314 | B4: =IF(A4="","",TEXT(A4,"ddd")) -> Mon | C4: =IF(A4="","",COUNTIF('Score Log'!$B$2:$B$501,A4)) -> 0 | G4: Commit days (marked Y) | H4: =COUNTIF($D$4:$D$23,"Y") -> 0
A5: 46316 | B5: =IF(A5="","",TEXT(A5,"ddd")) -> Wed | C5: =IF(A5="","",COUNTIF('Score Log'!$B$2:$B$501,A5)) -> 0 | G5: First commit date | H5: =IF(H4=0,"",_xlfn.MINIFS($A$4:$A$23,$D$4:$D$23,"Y"))
A6: 46321 | B6: =IF(A6="","",TEXT(A6,"ddd")) -> Mon | C6: =IF(A6="","",COUNTIF('Score Log'!$B$2:$B$501,A6)) -> 0 | G6: Last commit date | H6: =IF(H4=0,"",_xlfn.MAXIFS($A$4:$A$23,$D$4:$D$23,"Y"))
A7: 46323 | B7: =IF(A7="","",TEXT(A7,"ddd")) -> Wed | C7: =IF(A7="","",COUNTIF('Score Log'!$B$2:$B$501,A7)) -> 0 | G7: Commit span (days) | H7: =IF(H4=0,0,H6-H5) -> 0
A8: 46328 | B8: =IF(A8="","",TEXT(A8,"ddd")) -> Mon | C8: =IF(A8="","",COUNTIF('Score Log'!$B$2:$B$501,A8)) -> 0 | G8: Marks per commit day | H8: 5
A9: 46330 | B9: =IF(A9="","",TEXT(A9,"ddd")) -> Wed | C9: =IF(A9="","",COUNTIF('Score Log'!$B$2:$B$501,A9)) -> 0 | G9: Max commit days counted | H9: 3
B10: =IF(A10="","",TEXT(A10,"ddd")) | C10: =IF(A10="","",COUNTIF('Score Log'!$B$2:$B$501,A10)) | G10: Span bonus 1: more than (days) | H10: 7
B11: =IF(A11="","",TEXT(A11,"ddd")) | C11: =IF(A11="","",COUNTIF('Score Log'!$B$2:$B$501,A11)) | G11: Span bonus 2: more than (days) | H11: 14
B12: =IF(A12="","",TEXT(A12,"ddd")) | C12: =IF(A12="","",COUNTIF('Score Log'!$B$2:$B$501,A12)) | G12: Marks per span bonus | H12: 5
B13: =IF(A13="","",TEXT(A13,"ddd")) | C13: =IF(A13="","",COUNTIF('Score Log'!$B$2:$B$501,A13)) | G13: Part 1 GitHub marks (estimate) | H13: =MIN(MIN(H4,H9)*H8+IF(H7>H10,H12,0)+IF(H7>H11,H12,0),H9*H8+2*H12) -> 0
B14: =IF(A14="","",TEXT(A14,"ddd")) | C14: =IF(A14="","",COUNTIF('Score Log'!$B$2:$B$501,A14))
B15: =IF(A15="","",TEXT(A15,"ddd")) | C15: =IF(A15="","",COUNTIF('Score Log'!$B$2:$B$501,A15)) | G15: Rules from the brief: 5 marks per commit on separate days (up to 3), +5 if span > 1 week, +5 if > 2 weeks. Mark each date only once so days aren't double counted.
B16: =IF(A16="","",TEXT(A16,"ddd")) | C16: =IF(A16="","",COUNTIF('Score Log'!$B$2:$B$501,A16))
B17: =IF(A17="","",TEXT(A17,"ddd")) | C17: =IF(A17="","",COUNTIF('Score Log'!$B$2:$B$501,A17))
B18: =IF(A18="","",TEXT(A18,"ddd")) | C18: =IF(A18="","",COUNTIF('Score Log'!$B$2:$B$501,A18))
B19: =IF(A19="","",TEXT(A19,"ddd")) | C19: =IF(A19="","",COUNTIF('Score Log'!$B$2:$B$501,A19))
B20: =IF(A20="","",TEXT(A20,"ddd")) | C20: =IF(A20="","",COUNTIF('Score Log'!$B$2:$B$501,A20))
B21: =IF(A21="","",TEXT(A21,"ddd")) | C21: =IF(A21="","",COUNTIF('Score Log'!$B$2:$B$501,A21))
B22: =IF(A22="","",TEXT(A22,"ddd")) | C22: =IF(A22="","",COUNTIF('Score Log'!$B$2:$B$501,A22))
B23: =IF(A23="","",TEXT(A23,"ddd")) | C23: =IF(A23="","",COUNTIF('Score Log'!$B$2:$B$501,A23))
